<?xml version="1.0" ?>
<!-- =================================================================================== -->
<!-- |    This document was autogenerated by xacro from main_urdf.xacro                | -->
<!-- |    EDITING THIS FILE BY HAND IS NOT RECOMMENDED                                 | -->
<!-- =================================================================================== -->
<robot name="AmirMmv_BipedRobot_pkg">
  <material name="black">
    <color rgba="0.0 0.0 0.0 1.0"/>
  </material>
  <material name="blue">
    <color rgba="0.0 0.0 0.8 1.0"/>
  </material>
  <material name="green">
    <color rgba="0.0 0.8 0.0 1.0"/>
  </material>
  <material name="grey">
    <color rgba="0.6 0.6 0.6 1.0"/>
  </material>
  <material name="orange">
    <color rgba="1.0 0.4235294117647059 0.0392156862745098 1.0"/>
  </material>
  <material name="brown">
    <color rgba="0.8705882352941177 0.8117647058823529 0.7647058823529411 1.0"/>
  </material>
  <material name="red">
    <color rgba="0.8 0.0 0.0 1.0"/>
  </material>
  <material name="white">
    <color rgba="1.0 1.0 1.0 1.0"/>
  </material>
  <!-- ros_control plugin -->
  <gazebo>
    <plugin filename="libgazebo_ros_control.so" name="gazebo_ros_control">
      <robotNamespace>/amirmmv_bipedrobot_ns</robotNamespace>
    </plugin>
  </gazebo>
  <gazebo>
    <plugin filename="libgazebo_ros_p3d.so" name="ground_truth">
      <frameName>map</frameName>
      <bodyName>base_link</bodyName>
      <topicName>/amirmmv_bipedrobot_ns/odom</topicName>
      <updateRate>100.0</updateRate>
    </plugin>
  </gazebo>
  <!-- imu sensor -->
  <gazebo reference="imu_link">
    <gravity>true</gravity>
    <sensor name="imu_sensor" type="imu">
      <always_on>true</always_on>
      <update_rate>100</update_rate>
      <visualize>true</visualize>
      <topic>/amirmmv_bipedrobot_ns/Mysensor/imu</topic>
      <plugin filename="libgazebo_ros_imu_sensor.so" name="imu_plugin">
        <topicName>/amirmmv_bipedrobot_ns/Mysensor/imu</topicName>
        <bodyName>imu_link</bodyName>
        <updateRateHZ>10.0</updateRateHZ>
        <gaussianNoise>0.0</gaussianNoise>
        <xyzOffset>0 0 0</xyzOffset>
        <rpyOffset>0 0 0</rpyOffset>
        <frameName>imu_link</frameName>
      </plugin>
      <pose>0 0 0 0 0 0</pose>
    </sensor>
  </gazebo>
  <!-- World -->
  <gazebo reference="world"/>
  <!-- Map -->
  <gazebo reference="map"/>
  <!-- Base -->
  <gazebo reference="base_link"/>
  <!-- IMU -->
  <gazebo reference="imu_link"/>
  <!-- Body-->
  <gazebo reference="base_footprint">
    <mu1>0.2</mu1>
    <mu2>0.2</mu2>
    <material>Gazebo/Red</material>
    <selfCollide>false</selfCollide>
  </gazebo>
  <!-- Left Leg -->
  <gazebo reference="l_hip_yaw_link">
    <mu1>0.2</mu1>
    <mu2>0.2</mu2>
    <material>Gazebo/Grey</material>
    <selfCollide>false</selfCollide>
  </gazebo>
  <gazebo reference="l_hip_roll_link">
    <mu1>0.2</mu1>
    <mu2>0.2</mu2>
    <material>Gazebo/Grey</material>
    <selfCollide>false</selfCollide>
  </gazebo>
  <gazebo reference="l_hip_pitch_link">
    <mu1>0.2</mu1>
    <mu2>0.2</mu2>
    <material>Gazebo/Grey</material>
    <selfCollide>false</selfCollide>
  </gazebo>
  <gazebo reference="l_knee_pitch_link">
    <mu1>0.2</mu1>
    <mu2>0.2</mu2>
    <material>Gazebo/Grey</material>
    <selfCollide>false</selfCollide>
  </gazebo>
  <gazebo reference="l_ankle_pitch_link">
    <mu1>0.2</mu1>
    <mu2>0.2</mu2>
    <material>Gazebo/Blue</material>
    <selfCollide>false</selfCollide>
  </gazebo>
  <gazebo reference="l_ankle_roll_link">
    <!--  Edited -->
    <kp>100000.0</kp>
    <kd>100.0</kd>
    <collision names="collision_l_ankle_roll_link">
      <surface>
        <friction>
          <ode>
            <mu>0.7</mu>
            <mu2>0.7</mu2>
          </ode>
        </friction>
      </surface>
    </collision>
    <!--  Edited <mu1>1.5</mu1> -->
    <!--  Edited <mu2>1.5</mu2> -->
    <!--<maxContacts>30</maxContacts>-->
    <fdir1>1 1 0</fdir1>
    <maxVel>1.0</maxVel>
    <minDepth>0.001</minDepth>
    <material>Gazebo/Red</material>
  </gazebo>
  <!-- Right Leg -->
  <gazebo reference="r_hip_yaw_link">
    <mu1>0.2</mu1>
    <mu2>0.2</mu2>
    <material>Gazebo/Grey</material>
    <selfCollide>false</selfCollide>
  </gazebo>
  <gazebo reference="r_hip_roll_link">
    <mu1>0.2</mu1>
    <mu2>0.2</mu2>
    <material>Gazebo/Grey</material>
    <selfCollide>false</selfCollide>
  </gazebo>
  <gazebo reference="r_hip_pitch_link">
    <mu1>0.2</mu1>
    <mu2>0.2</mu2>
    <material>Gazebo/Grey</material>
    <selfCollide>false</selfCollide>
  </gazebo>
  <gazebo reference="r_knee_pitch_link">
    <mu1>0.2</mu1>
    <mu2>0.2</mu2>
    <material>Gazebo/Grey</material>
    <selfCollide>false</selfCollide>
  </gazebo>
  <gazebo reference="r_ankle_pitch_link">
    <mu1>0.2</mu1>
    <mu2>0.2</mu2>
    <material>Gazebo/Blue</material>
    <selfCollide>false</selfCollide>
  </gazebo>
  <gazebo reference="r_ankle_roll_link">
    <collision names="collision_l_ankle_roll_link">
      <surface>
        <friction>
          <ode>
            <mu>0.7</mu>
            <mu2>0.7</mu2>
          </ode>
        </friction>
      </surface>
    </collision>
    <kp>100000.0</kp>
    <kd>100.0</kd>
    <!--  Edited <mu1>1.5</mu1> -->
    <!--  Edited <mu2>1.5</mu2> -->
    <!--<maxContacts>30</maxContacts>-->
    <fdir1>1 1 0</fdir1>
    <maxVel>1.0</maxVel>
    <minDepth>0.0001</minDepth>
    <material>Gazebo/Red</material>
  </gazebo>
  <!--   ********** Contact sensors***********    -->
  <gazebo reference="l_ankle_roll_link">
    <sensor name="contact_l_foot_Amir" type="contact">
      <alwaysOn>true</alwaysOn>
      <update_rate>20.000000</update_rate>
      <contact>
        <collision>
          <origin rpy="0 0 0" xyz="0 0 0"/>
          <geometry>
            <mesh filename="package://amirmmv_bipedrobot_pkg/meshes/l_ankle_roll.stl" scale="1 1 1"/>
          </geometry>
          <material name="grey"/>
        </collision>
        <topic>/l_foot_contact_sensor</topic>
      </contact>
      <plugin filename="libgazebo_ros_bumper.so" name="gazebo_ros_bumper_controller">
        <bumperTopicName>l_bumper_topic</bumperTopicName>
        <frameName>l_frameName</frameName>
      </plugin>
    </sensor>
  </gazebo>
  <gazebo reference="r_ankle_roll_link">
    <sensor name="contact_r_foot_Amir" type="contact">
      <alwaysOn>true</alwaysOn>
      <selfCollide>true</selfCollide>
      <update_rate>20.000000</update_rate>
      <contact>
        <collision>
          <origin rpy="0 0 0" xyz="0 0 0"/>
          <geometry>
            <mesh filename="package://amirmmv_bipedrobot_pkg/meshes/r_ankle_pitch.stl" scale="1 1 1"/>
          </geometry>
          <material name="grey"/>
        </collision>
        <topic>/r_foot_contact_sensor</topic>
      </contact>
      <plugin filename="libgazebo_ros_bumper.so" name="gazebo_ros_bumper_controller">
        <bumperTopicName>r_bumper_topic</bumperTopicName>
        <frameName>r_frameName</frameName>
      </plugin>
    </sensor>
  </gazebo>
  <link name="base_link"/>
  <joint name="base_fixed" type="fixed">
    <origin rpy="0 0 0" xyz="0 0 0.1"/>
    <parent link="base_link"/>
    <child link="base_footprint"/>
  </joint>
  <!-- base_link -->
  <link name="base_footprint">
    <visual>
      <origin rpy="0 0 0" xyz="0 0 0"/>
      <geometry>
        <mesh filename="package://amirmmv_bipedrobot_pkg/meshes/base.stl" scale="1 1.25 1"/>
      </geometry>
      <material name="gray"/>
    </visual>
    <collision>
      <origin rpy="0 0 0" xyz="0 0 0"/>
      <geometry>
        <mesh filename="package://amirmmv_bipedrobot_pkg/meshes/base.stl" scale="1 1.25 1"/>
      </geometry>
      <material name="gray"/>
    </collision>
    <inertial>
      <origin xyz="-0.00856879 0.00000000 -0.02356598"/>
      <mass value="0.664564"/>
      <inertia ixx="0.00504324" ixy="-0.00000002" ixz="-0.00000358" iyy="0.00051942" iyz="0.00000000" izz="0.00510248"/>
    </inertial>
  </link>
  <!-- imu joint  -->
  <joint name="imu_fixed" type="fixed">
    <origin rpy="0 0 0" xyz="0 0 0.45"/>
    <parent link="base_footprint"/>
    <child link="imu_link"/>
  </joint>
  <link name="imu_link"/>
  <!-- right hip yaw joint 0.0 -0.09 -0.073 -->
  <joint name="r_hip_yaw_joint" type="fixed">
    <axis xyz="0 0 1"/>
    <origin rpy="0 0 -1.570796327" xyz="0.0 -0.09 -0.118"/>
    <parent link="base_footprint"/>
    <child link="r_hip_yaw_link"/>
    <!--            <limit effort="${dxl_effort}" lower="${-0.8}" upper="${0.8}" velocity="${dxl_speed}"/>
           <dynamics damping="0.01" friction="0.1"/>
-->
  </joint>
  <!--        <xacro:insert_transmission name="r_hip_yaw_joint"/>
-->
  <!-- right hip yaw link -->
  <link name="r_hip_yaw_link">
    <visual>
      <origin rpy="0 0 0" xyz="0 0 0"/>
      <geometry>
        <mesh filename="package://amirmmv_bipedrobot_pkg/meshes/r_hip_yaw.stl" scale="1 1 1"/>
      </geometry>
      <material name="grey"/>
    </visual>
    <collision>
      <origin rpy="0 0 0" xyz="0 0 0"/>
      <geometry>
        <mesh filename="package://amirmmv_bipedrobot_pkg/meshes/r_hip_yaw.stl" scale="1 1 1"/>
      </geometry>
      <material name="grey"/>
    </collision>
    <inertial>
      <origin xyz="0.00000000 -0.01999 -0.00735017"/>
      <mass value="0.090718"/>
      <inertia ixx="0.00014114" ixy="0.00000000" ixz="0.00000000" iyy="0.00002016" iyz="0.00000000" izz="0.00014272"/>
    </inertial>
  </link>
  <!-- right hip roll joint 0.0285 0.005 0.0487 -->
  <joint name="r_hip_roll_joint" type="revolute">
    <axis xyz="0 0 1"/>
    <origin rpy="1.570796327 0 3.141592654" xyz="0.0285 -0.005 0.0537"/>
    <parent link="r_hip_yaw_link"/>
    <child link="r_hip_roll_link"/>
    <limit effort="10" lower="-0.5" upper="0.5" velocity="2"/>
    <dynamics damping="0.01" friction="0.1"/>
  </joint>
  <transmission name="r_hip_roll_joint_tran">
    <type>transmission_interface/SimpleTransmission</type>
    <joint name="r_hip_roll_joint">
      <hardwareInterface>hardware_interface/EffortJointInterface</hardwareInterface>
    </joint>
    <actuator name="r_hip_roll_joint_motor">
      <hardwareInterface>EffortJointInterface</hardwareInterface>
      <mechanicalReduction>1</mechanicalReduction>
    </actuator>
  </transmission>
  <!-- right hip roll link -->
  <link name="r_hip_roll_link">
    <visual>
      <origin rpy="0 0 0" xyz="0 0 0"/>
      <geometry>
        <mesh filename="package://amirmmv_bipedrobot_pkg/meshes/r_hip_roll.stl" scale="1 1 1"/>
      </geometry>
      <material name="grey"/>
    </visual>
    <collision>
      <origin rpy="0 0 0" xyz="0 0 0"/>
      <geometry>
        <mesh filename="package://amirmmv_bipedrobot_pkg/meshes/r_hip_roll.stl" scale="1 1 1"/>
      </geometry>
      <material name="grey"/>
    </collision>
    <inertial>
      <origin xyz="-0.00005878 -0.01433229 -0.01958936"/>
      <mass value="0.342"/>
      <inertia ixx="0.00033963" ixy="0.00000054" ixz="-0.00000042" iyy="0.00029059" iyz="0.00001145" izz="0.00015024"/>
    </inertial>
  </link>
  <!-- right hip pitch joint 0 -0.084 0.0060 -->
  <joint name="r_hip_pitch_joint" type="revolute">
    <axis xyz="0 0 1"/>
    <origin rpy="-1.570796327 0 -1.570796327" xyz="0 -0.084 0.0000"/>
    <parent link="r_hip_roll_link"/>
    <child link="r_hip_pitch_link"/>
    <limit effort="10" lower="-1.396" upper="1.396" velocity="2"/>
    <dynamics damping="0.01" friction="0.1"/>
  </joint>
  <transmission name="r_hip_pitch_joint_tran">
    <type>transmission_interface/SimpleTransmission</type>
    <joint name="r_hip_pitch_joint">
      <hardwareInterface>hardware_interface/EffortJointInterface</hardwareInterface>
    </joint>
    <actuator name="r_hip_pitch_joint_motor">
      <hardwareInterface>EffortJointInterface</hardwareInterface>
      <mechanicalReduction>1</mechanicalReduction>
    </actuator>
  </transmission>
  <!-- right hip pitch link -->
  <link name="r_hip_pitch_link">
    <visual>
      <origin rpy="0 0 0" xyz="0 0 0"/>
      <geometry>
        <mesh filename="package://amirmmv_bipedrobot_pkg/meshes/r_hip_pitch.stl" scale="1 1 1"/>
      </geometry>
      <material name="grey"/>
    </visual>
    <collision>
      <origin rpy="0 0 0" xyz="0 0 0"/>
      <geometry>
        <mesh filename="package://amirmmv_bipedrobot_pkg/meshes/r_hip_pitch.stl" scale="1 1 1"/>
      </geometry>
      <material name="grey"/>
    </collision>
    <inertial>
      <origin xyz="0.21422113 0.0 0.0"/>
      <mass value="0.33732478"/>
      <inertia ixx="0.00012533" ixy="0.00000000" ixz="0.00000079" iyy="0.00295762" iyz="0.00000000" izz="0.00291401"/>
    </inertial>
  </link>
  <!-- right knee pitch joint 0.34 0 0 -->
  <joint name="r_knee_pitch_joint" type="revolute">
    <axis xyz="0 0 1"/>
    <origin rpy="0 0 0" xyz="0.34 0 0"/>
    <parent link="r_hip_pitch_link"/>
    <child link="r_knee_pitch_link"/>
    <limit effort="10" lower="0.0" upper="1.4" velocity="2"/>
    <dynamics damping="0.01" friction="0.1"/>
  </joint>
  <transmission name="r_knee_pitch_joint_tran">
    <type>transmission_interface/SimpleTransmission</type>
    <joint name="r_knee_pitch_joint">
      <hardwareInterface>hardware_interface/EffortJointInterface</hardwareInterface>
    </joint>
    <actuator name="r_knee_pitch_joint_motor">
      <hardwareInterface>EffortJointInterface</hardwareInterface>
      <mechanicalReduction>1</mechanicalReduction>
    </actuator>
  </transmission>
  <!-- right knee pitch link -->
  <link name="r_knee_pitch_link">
    <visual>
      <origin rpy="0 0 0" xyz="0 0 0"/>
      <geometry>
        <mesh filename="package://amirmmv_bipedrobot_pkg/meshes/r_knee_pitch.stl" scale="1 1 1"/>
      </geometry>
      <material name="grey"/>
    </visual>
    <collision>
      <origin rpy="0 0 0" xyz="0 0 0"/>
      <geometry>
        <mesh filename="package://amirmmv_bipedrobot_pkg/meshes/r_knee_pitch.stl" scale="1 1 1"/>
      </geometry>
      <material name="grey"/>
    </collision>
    <inertial>
      <origin xyz="0.16288151 0.00000000 0.00000000"/>
      <mass value="0.15100000"/>
      <inertia ixx="0.0000634" ixy="0.0" ixz="0.0" iyy="0.00139615" iyz="0.0" izz="0.00136734"/>
    </inertial>
  </link>
  <!-- right ankle pitch joint 0.28 0 0 -->
  <joint name="r_ankle_pitch_joint" type="revolute">
    <axis xyz="0 0 1"/>
    <origin rpy="0 0 0" xyz="0.3 0 0"/>
    <parent link="r_knee_pitch_link"/>
    <child link="r_ankle_pitch_link"/>
    <limit effort="10" lower="-0.349" upper="1.047" velocity="2"/>
    <dynamics damping="0.01" friction="0.1"/>
  </joint>
  <transmission name="r_ankle_pitch_joint_tran">
    <type>transmission_interface/SimpleTransmission</type>
    <joint name="r_ankle_pitch_joint">
      <hardwareInterface>hardware_interface/EffortJointInterface</hardwareInterface>
    </joint>
    <actuator name="r_ankle_pitch_joint_motor">
      <hardwareInterface>EffortJointInterface</hardwareInterface>
      <mechanicalReduction>1</mechanicalReduction>
    </actuator>
  </transmission>
  <!-- right ankle pitch link -->
  <link name="r_ankle_pitch_link">
    <visual>
      <origin rpy="0 0 0" xyz="0 0 0"/>
      <geometry>
        <mesh filename="package://amirmmv_bipedrobot_pkg/meshes/r_ankle_pitch.stl" scale="1 1 1"/>
      </geometry>
      <material name="grey"/>
    </visual>
    <collision>
      <origin rpy="0 0 0" xyz="0 0 0"/>
      <geometry>
        <mesh filename="package://amirmmv_bipedrobot_pkg/meshes/r_ankle_pitch.stl" scale="1 1 1"/>
      </geometry>
      <material name="grey"/>
    </collision>
    <inertial>
      <origin xyz="-0.01433229 0.01958936 0.00005878"/>
      <mass value="0.342"/>
      <inertia ixx="0.00029059" ixy="-0.00001145" ixz="-0.00000054" iyy="0.00015024" iyz="-0.00000042" izz="0.00033963"/>
    </inertial>
  </link>
  <!-- right ankle roll  0.01 0 0 -->
  <joint name="r_ankle_roll_joint" type="revolute">
    <axis xyz="0 0 1"/>
    <origin rpy="1.570796327 0 0" xyz="-0.01 0 0"/>
    <parent link="r_ankle_pitch_link"/>
    <child link="r_ankle_roll_link"/>
    <limit effort="10" lower="-0.5" upper="0.5" velocity="2"/>
    <dynamics damping="0.01" friction="0.1"/>
  </joint>
  <transmission name="r_ankle_roll_joint_tran">
    <type>transmission_interface/SimpleTransmission</type>
    <joint name="r_ankle_roll_joint">
      <hardwareInterface>hardware_interface/EffortJointInterface</hardwareInterface>
    </joint>
    <actuator name="r_ankle_roll_joint_motor">
      <hardwareInterface>EffortJointInterface</hardwareInterface>
      <mechanicalReduction>1</mechanicalReduction>
    </actuator>
  </transmission>
  <!-- right ankle roll link -->
  <link name="r_ankle_roll_link">
    <visual>
      <origin rpy="0 0 0" xyz="0 0 0"/>
      <geometry>
        <mesh filename="package://amirmmv_bipedrobot_pkg/meshes/r_ankle_roll.stl" scale="1 1 1"/>
      </geometry>
      <material name="grey"/>
    </visual>
    <collision>
      <origin rpy="0 0 0" xyz="0 0 0"/>
      <geometry>
        <mesh filename="package://amirmmv_bipedrobot_pkg/meshes/r_ankle_roll.stl" scale="1 1 1"/>
      </geometry>
      <material name="grey"/>
    </collision>
    <inertial>
      <origin xyz="0.03627101 -0.00000116 0.00053793"/>
      <mass value="0.155"/>
      <inertia ixx="0.00052206" ixy="0" ixz="0.00001" iyy="0.00047025" iyz="0" izz="0.00009087"/>
    </inertial>
  </link>
  <!-- right ft fixed joint -->
  <joint name="r_ft_fixed" type="fixed">
    <origin rpy="0 -1.570796327 0" xyz="0.045 0.0 0.0"/>
    <parent link="r_ankle_roll_link"/>
    <child link="r_foot_ft_link"/>
  </joint>
  <!-- right foot ft link -->
  <link name="r_foot_ft_link"/>
  <!-- left hip yaw joint -->
  <joint name="l_hip_yaw_joint" type="fixed">
    <axis xyz="0 0 1"/>
    <origin rpy="0 0 1.570796327" xyz="0.0 0.09 -0.108"/>
    <parent link="base_footprint"/>
    <child link="l_hip_yaw_link"/>
  </joint>
  <!-- left hip yaw link -->
  <link name="l_hip_yaw_link">
    <visual>
      <origin rpy="0 0 0" xyz="0 0 0"/>
      <geometry>
        <mesh filename="package://amirmmv_bipedrobot_pkg/meshes/l_hip_yaw.stl" scale="1 1 1"/>
      </geometry>
      <material name="grey"/>
    </visual>
    <collision>
      <origin rpy="0 0 0" xyz="0 0 0"/>
      <geometry>
        <mesh filename="package://amirmmv_bipedrobot_pkg/meshes/l_hip_yaw.stl" scale="1 1 1"/>
      </geometry>
      <material name="grey"/>
    </collision>
    <inertial>
      <origin xyz="0 0.01999 -0.00735017"/>
      <mass value="0.090718"/>
      <inertia ixx="0.00014114" ixy="0.0" ixz="0.0" iyy="0.00002016" iyz="0.0" izz="0.00014272"/>
    </inertial>
  </link>
  <!-- left hip roll joint-->
  <joint name="l_hip_roll_joint" type="revolute">
    <axis xyz="0 0 1"/>
    <origin rpy="1.570796327 0 0" xyz="0.0285 0.005 0.0450"/>
    <parent link="l_hip_yaw_link"/>
    <child link="l_hip_roll_link"/>
    <limit effort="10" lower="-0.5" upper="0.5" velocity="2"/>
    <dynamics damping="0.01" friction="0.1"/>
  </joint>
  <transmission name="l_hip_roll_joint_tran">
    <type>transmission_interface/SimpleTransmission</type>
    <joint name="l_hip_roll_joint">
      <hardwareInterface>hardware_interface/EffortJointInterface</hardwareInterface>
    </joint>
    <actuator name="l_hip_roll_joint_motor">
      <hardwareInterface>EffortJointInterface</hardwareInterface>
      <mechanicalReduction>1</mechanicalReduction>
    </actuator>
  </transmission>
  <!-- left hip roll link -->
  <link name="l_hip_roll_link">
    <visual>
      <origin rpy="0 0 0" xyz="0 0 0"/>
      <geometry>
        <mesh filename="package://amirmmv_bipedrobot_pkg/meshes/l_hip_roll.stl" scale="1 1 1"/>
      </geometry>
      <material name="grey"/>
    </visual>
    <collision>
      <origin rpy="0 0 0" xyz="0 0 0"/>
      <geometry>
        <mesh filename="package://amirmmv_bipedrobot_pkg/meshes/l_hip_roll.stl" scale="1 1 1"/>
      </geometry>
      <material name="grey"/>
    </collision>
    <inertial>
      <origin xyz="-0.00005878 -0.01433229 -0.01958936"/>
      <mass value="0.342"/>
      <inertia ixx="0.00033963" ixy="0.00000054" ixz="-0.00000042" iyy="0.00029059" iyz="0.00001145" izz="0.00015024"/>
    </inertial>
  </link>
  <!-- left hip pitch joint -->
  <joint name="l_hip_pitch_joint" type="revolute">
    <axis xyz="0 0 1"/>
    <origin rpy="-1.570796327 0 -1.570796327" xyz="0 -0.084 0.0060"/>
    <parent link="l_hip_roll_link"/>
    <child link="l_hip_pitch_link"/>
    <limit effort="10" lower="-1.396" upper="1.396" velocity="2"/>
    <dynamics damping="0.01" friction="0.1"/>
  </joint>
  <transmission name="l_hip_pitch_joint_tran">
    <type>transmission_interface/SimpleTransmission</type>
    <joint name="l_hip_pitch_joint">
      <hardwareInterface>hardware_interface/EffortJointInterface</hardwareInterface>
    </joint>
    <actuator name="l_hip_pitch_joint_motor">
      <hardwareInterface>EffortJointInterface</hardwareInterface>
      <mechanicalReduction>1</mechanicalReduction>
    </actuator>
  </transmission>
  <!-- left hip pitch link -->
  <link name="l_hip_pitch_link">
    <visual>
      <origin rpy="0 0 0" xyz="0 0 0"/>
      <geometry>
        <mesh filename="package://amirmmv_bipedrobot_pkg/meshes/l_hip_pitch.stl" scale="1 1 1"/>
      </geometry>
      <material name="grey"/>
    </visual>
    <collision>
      <origin rpy="0 0 0" xyz="0 0 0"/>
      <geometry>
        <mesh filename="package://amirmmv_bipedrobot_pkg/meshes/l_hip_pitch.stl" scale="1 1 1"/>
      </geometry>
      <material name="grey"/>
    </collision>
    <inertial>
      <origin xyz="0.21422113 0.00000000 0.00000000"/>
      <mass value="0.33732478"/>
      <inertia ixx="0.00012533" ixy="0.00000000" ixz="0.00000079" iyy="0.00295762" iyz="0.00000000" izz="0.00291401"/>
    </inertial>
  </link>
  <!-- left knee pitch joint -->
  <joint name="l_knee_pitch_joint" type="revolute">
    <axis xyz="0 0 1"/>
    <origin rpy="0 0 0" xyz="0.34 0 0"/>
    <parent link="l_hip_pitch_link"/>
    <child link="l_knee_pitch_link"/>
    <limit effort="10" lower="0" upper="1.4" velocity="2"/>
    <dynamics damping="0.01" friction="0.1"/>
  </joint>
  <transmission name="l_knee_pitch_joint_tran">
    <type>transmission_interface/SimpleTransmission</type>
    <joint name="l_knee_pitch_joint">
      <hardwareInterface>hardware_interface/EffortJointInterface</hardwareInterface>
    </joint>
    <actuator name="l_knee_pitch_joint_motor">
      <hardwareInterface>EffortJointInterface</hardwareInterface>
      <mechanicalReduction>1</mechanicalReduction>
    </actuator>
  </transmission>
  <!-- left knee pitch link -->
  <link name="l_knee_pitch_link">
    <visual>
      <origin rpy="0 0 0" xyz="0 0 0"/>
      <geometry>
        <mesh filename="package://amirmmv_bipedrobot_pkg/meshes/l_knee_pitch.stl" scale="1 1 1"/>
      </geometry>
      <material name="grey"/>
    </visual>
    <collision>
      <origin rpy="0 0 0" xyz="0 0 0"/>
      <geometry>
        <mesh filename="package://amirmmv_bipedrobot_pkg/meshes/l_knee_pitch.stl" scale="1 1 1"/>
      </geometry>
      <material name="grey"/>
    </collision>
    <inertial>
      <origin xyz="0.16288151 0.00000000 0.00000000"/>
      <mass value="0.15100000"/>
      <inertia ixx="0.0000634" ixy="0.0" ixz="0.0" iyy="0.00139615" iyz="0.0" izz="0.00136734"/>
    </inertial>
  </link>
  <!-- left ankle pitch joint -->
  <joint name="l_ankle_pitch_joint" type="revolute">
    <axis xyz="0 0 1"/>
    <origin rpy="0 0 0" xyz="0.28 0 0"/>
    <parent link="l_knee_pitch_link"/>
    <child link="l_ankle_pitch_link"/>
    <limit effort="10" lower="-0.349" upper="1.047" velocity="2"/>
    <dynamics damping="0.01" friction="0.1"/>
  </joint>
  <transmission name="l_ankle_pitch_joint_tran">
    <type>transmission_interface/SimpleTransmission</type>
    <joint name="l_ankle_pitch_joint">
      <hardwareInterface>hardware_interface/EffortJointInterface</hardwareInterface>
    </joint>
    <actuator name="l_ankle_pitch_joint_motor">
      <hardwareInterface>EffortJointInterface</hardwareInterface>
      <mechanicalReduction>1</mechanicalReduction>
    </actuator>
  </transmission>
  <!-- left ankle pitch link -->
  <link name="l_ankle_pitch_link">
    <visual>
      <origin rpy="0 0 0" xyz="0 0 0"/>
      <geometry>
        <mesh filename="package://amirmmv_bipedrobot_pkg/meshes/l_ankle_pitch.stl" scale="1 1 1"/>
      </geometry>
      <material name="grey"/>
    </visual>
    <collision>
      <origin rpy="0 0 0" xyz="0 0 0"/>
      <geometry>
        <mesh filename="package://amirmmv_bipedrobot_pkg/meshes/l_ankle_pitch.stl" scale="1 1 1"/>
      </geometry>
      <material name="grey"/>
    </collision>
    <inertial>
      <origin xyz="-0.01433229 0.01958936 0.00005878"/>
      <mass value="0.34200000"/>
      <inertia ixx="0.00029059" ixy="-0.00001145" ixz="-0.00000054" iyy="0.00015024" iyz="-0.00000042" izz="0.00033963"/>
    </inertial>
  </link>
  <!-- left ankle roll pitch -->
  <joint name="l_ankle_roll_joint" type="revolute">
    <axis xyz="0 0 1"/>
    <origin rpy="1.570796327 0 0" xyz="0.01 0 0"/>
    <parent link="l_ankle_pitch_link"/>
    <child link="l_ankle_roll_link"/>
    <limit effort="10" lower="-0.5" upper="0.5" velocity="2"/>
    <dynamics damping="0.1" friction="0.01"/>
  </joint>
  <transmission name="l_ankle_roll_joint_tran">
    <type>transmission_interface/SimpleTransmission</type>
    <joint name="l_ankle_roll_joint">
      <hardwareInterface>hardware_interface/EffortJointInterface</hardwareInterface>
    </joint>
    <actuator name="l_ankle_roll_joint_motor">
      <hardwareInterface>EffortJointInterface</hardwareInterface>
      <mechanicalReduction>1</mechanicalReduction>
    </actuator>
  </transmission>
  <!-- left ankle roll link -->
  <link name="l_ankle_roll_link">
    <visual>
      <origin rpy="0 0 0" xyz="0 0 0"/>
      <geometry>
        <mesh filename="package://amirmmv_bipedrobot_pkg/meshes/l_ankle_roll.stl" scale="1 1 1"/>
      </geometry>
      <material name="grey"/>
    </visual>
    <collision>
      <origin rpy="0 0 0" xyz="0 0 0"/>
      <geometry>
        <mesh filename="package://amirmmv_bipedrobot_pkg/meshes/l_ankle_roll.stl" scale="1 1 1"/>
      </geometry>
      <material name="grey"/>
    </collision>
    <inertial>
      <origin xyz="0.03627101 -0.00000116 0.00053793"/>
      <mass value="0.155"/>
      <inertia ixx="0.00052206" ixy="0.000000" ixz="0.00001" iyy="0.00047025" iyz="0" izz="0.00009087"/>
    </inertial>
  </link>
  <!-- left ft fixed joint -->
  <joint name="l_ft_fixed" type="fixed">
    <origin rpy="0 -1.570796327 0" xyz="0.045 0.0 0.0"/>
    <parent link="l_ankle_roll_link"/>
    <child link="l_foot_ft_link"/>
  </joint>
  <!-- left foot ft link -->
  <link name="l_foot_ft_link">
         </link>
</robot>
